Workbook

Sheet Tipo
A1: Tipo | B1: ID | C1: R Time | D1: Area FAMEx | E1: TCF (Rx) | F1: W TAG is | G1: WFAMEX | H1: F FAx | I1: % Area | J1: W x | K1: g/100g Ac g [% p/p] | L1: Wts (g) | N1: PARAMETRO | O1: %FAME | P1: g ac. g./100 g grasa
A2: Sat | B2: C4:0 | C2: 2.688 | D2: =VLOOKUP(B2,'Reporte GC'!C1:H54,5,FALSE) -> 0 | E2: 1.5929 | F2: =O$21 -> 0.0020467305 | G2: =(D2*F2*1*E2)/$D$44 -> 0 | H2: 0.8626 | I2: =D2*100/$D$52 -> 0 | J2: =H2*G2 -> 0 | K2: =(J2/L2)*100 -> 0 | L2: =N21 -> 0.034
A3: Sat | B3: C6:0 | C3: 4.758 | D3: =VLOOKUP(B3,'Reporte GC'!C1:H54,5,FALSE) -> 0 | E3: 1.3537 | F3: =O$21 -> 0.0020467305 | G3: =(D3*F3*1*E3)/$D$44 -> 0 | H3: 0.8922 | I3: =D3*100/$D$52 -> 0 | J3: =H3*G3 -> 0 | K3: =(J3/L3)*100 -> 0 | L3: =L2 -> 0.034 | N3: Total Ac. Grasos | O3: =SUM(I2:I43,I45:I50) -> 99.983591 | P3: =SUM(K2:K50) -> 92.647611
A4: Sat | B4: C8:0 | C4: 6.563 | D4: =VLOOKUP(B4,'Reporte GC'!C1:H54,5,FALSE) -> 0 | E4: 1.234 | F4: =O$21 -> 0.0020467305 | G4: =(D4*F4*1*E4)/$D$44 -> 0 | H4: 0.9114 | I4: =D4*100/$D$52 -> 0 | J4: =H4*G4 -> 0 | K4: =(J4/L4)*100 -> 0 | L4: =L3 -> 0.034 | N4: Grasa saturadas | O4: =+SUM(I2,I3,I4,I5,I6,I7,I8,I9,I11,I13,I16,I20,I31,I36,I41,I48) -> 6.8591924 | P4: =SUM(K2,K3,K4,K5,K6,K7,K8,K9,K11,K13,K16,K20,K31,K36,K41,K48) -> 6.4648541
A5: Sat | B5: C10:0 | C5: 8.259 | D5: =VLOOKUP(B5,'Reporte GC'!C1:H54,5,FALSE) -> 0 | E5: 1.1623 | F5: =O$21 -> 0.0020467305 | G5: =(D5*F5*1*E5)/$D$44 -> 0 | H5: 0.9247 | I5: =D5*100/$D$52 -> 0 | J5: =H5*G5 -> 0 | K5: =(J5/L5)*100 -> 0 | L5: =L4 -> 0.034 | N5: Grasa cis_monoinsaturadas | O5: =SUM(I10,I12,I14,I18,I21,I23,I32,I33,I42,I50) -> 4.5560385 | P5: =SUM(K10,K12,K14,K18,K21,K23,K32,K33,K42,K50) -> 4.2203273
A6: Sat | B6: C11:0 | C6: 9.304 | D6: =VLOOKUP(B6,'Reporte GC'!C1:H54,5,FALSE) -> 0 | E6: 1.1362 | F6: =O$21 -> 0.0020467305 | G6: =(D6*F6*1*E6)/$D$44 -> 0 | H6: 0.93 | I6: =D6*100/$D$52 -> 0 | J6: =H6*G6 -> 0 | K6: =(J6/L6)*100 -> 0 | L6: =L5 -> 0.034 | N6: Grasa cis poliinsaturadas | O6: =SUM(I15,I17,I19,I24,I26,I27,I28,I29,I30,I34,I35,I37,I38,I39,I40,I43,I45,I47,I49,I46) -> 34.251159 | P6: =SUM(K15,K17,K19,K24,K26,K27,K28,K29,K30,K34,K35,K37,K38,K39,K40,K43,K47,K49,K45,K46) -> 31.504133
A7: Sat | B7: C12:0 | C7: 10.614 | D7: =VLOOKUP(B7,'Reporte GC'!C1:H54,5,FALSE) -> 0 | E7: 1.1144 | F7: =O$21 -> 0.0020467305 | G7: =(D7*F7*1*E7)/$D$44 -> 0 | H7: 0.9346 | I7: =D7*100/$D$52 -> 0 | J7: =H7*G7 -> 0 | K7: =(J7/L7)*100 -> 0 | L7: =L6 -> 0.034 | N7: Grasa EPA (C20:5) | O7: =+I40 -> 3.910633 | P7: =+K40 -> 3.5389292
A8: Sat | B8: C13:0 | C8: 12.329 | D8: =VLOOKUP(B8,'Reporte GC'!C1:H54,5,FALSE) -> 0 | E8: 1.096 | F8: =O$21 -> 0.0020467305 | G8: =(D8*F8*1*E8)/$D$44 -> 0 | H8: 0.9386 | I8: =D8*100/$D$52 -> 0 | J8: =H8*G8 -> 0 | K8: =(J8/L8)*100 -> 0 | L8: =L7 -> 0.034 | N8: Grasa DHA (C22:6) | O8: =+I49 -> 4.1253969 | P8: =+K49 -> 3.8456433
A9: Sat | B9: C14:0 | C9: 14.302 | D9: =VLOOKUP(B9,'Reporte GC'!C1:H54,5,FALSE) -> 20.314318 | E9: 1.0802 | F9: =O$21 -> 0.0020467305 | G9: =(D9*F9*1*E9)/$D$44 -> 5.4196254e-05 | H9: 0.9421 | I9: =D9*100/$D$52 -> 0.15552976 | J9: =H9*G9 -> 5.1058291e-05 | K9: =(J9/L9)*100 -> 0.15017144 | L9: =L8 -> 0.034 | N9: W-3PUFAs | O9: =+I29+I30+I38+I39+I45+I40+I47+I49 -> 17.060328 | P9: =+K29+K30+K38+K39+K45+K40+K47+K49 -> 15.648754
A10: M.insat | B10: C14:1 | C10: 15.095 | D10: =VLOOKUP(B10,'Reporte GC'!C1:H54,5,FALSE) -> 0 | E10: 1.0713 | F10: =O$21 -> 0.0020467305 | G10: =(D10*F10*1*E10)/$D$44 -> 0 | H10: 0.9416 | I10: =D10*100/$D$52 -> 0 | J10: =H10*G10 -> 0 | K10: =(J10/L10)*100 -> 0 | L10: =L9 -> 0.034 | N10: W-6PUFAs | O10: =SUM(I24,I27,I34,I35,I43,I37,I46) -> 17.134076 | P10: =+K24+K27+K34+K35+K37+K43+K46 -> 15.803412
A11: Sat | B11: C15:0 | C11: 16.695 | D11: =VLOOKUP(B11,'Reporte GC'!C1:H54,5,FALSE) -> 0 | E11: 1.0666 | F11: =O$21 -> 0.0020467305 | G11: =(D11*F11*1*E11)/$D$44 -> 0 | H11: 0.9453 | I11: =D11*100/$D$52 -> 0 | J11: =H11*G11 -> 0 | K11: =(J11/L11)*100 -> 0 | L11: =L10 -> 0.034 | N11: No Identificados | O11: =I51 -> 0.016409018 | P11: =K51 -> 0.014790365
A12: M.insat | B12: C15:1 | C12: 17.61 | D12: =VLOOKUP(B12,'Reporte GC'!C1:H54,5,FALSE) -> 0 | E12: 1.0582 | F12: =O$21 -> 0.0020467305 | G12: =(D12*F12*1*E12)/$D$44 -> 0 | H12: 0.99449 | I12: =D12*100/$D$52 -> 0 | J12: =H12*G12 -> 0 | K12: =(J12/L12)*100 -> 0 | L12: =L11 -> 0.034 | N12: W6/W3 | O12: =O10/O9 -> 1.0043228 | P12: =P10/P9 -> 1.0098831
A13: Sat | B13: C16:0 | C13: 19.42 | D13: =VLOOKUP(B13,'Reporte GC'!C1:H54,5,FALSE) -> 528.88953 | E13: 1.0546 | F13: =O$21 -> 0.0020467305 | G13: =(D13*F13*1*E13)/$D$44 -> 0.0013775761 | H13: 0.9481 | I13: =D13*100/$D$52 -> 4.0492652 | J13: =H13*G13 -> 0.0013060799 | K13: =(J13/L13)*100 -> 3.8414114 | L13: =L12 -> 0.034
A14: M.insat | B14: C16:1 | C14: 20.06 | D14: =VLOOKUP(B14,'Reporte GC'!C1:H54,5,FALSE) -> 29.766155 | E14: 1.0468 | F14: =O$21 -> 0.0020467305 | G14: =(D14*F14*1*E14)/$D$44 -> 7.695721e-05 | H14: 0.9477 | I14: =D14*100/$D$52 -> 0.22789458 | J14: =H14*G14 -> 7.2932348e-05 | K14: =(J14/L14)*100 -> 0.21450691 | L14: =L13 -> 0.034
A15: P.insat | B15: C16:2n4 | D15: =VLOOKUP(B15,'Reporte GC'!C1:H54,5,FALSE) -> 0 | E15: 1.0468 | F15: =O$21 -> 0.0020467305 | G15: =(D15*F15*1*E15)/$D$44 -> 0 | H15: 0.9477 | I15: =D15*100/$D$52 -> 0 | J15: =H15*G15 -> 0 | K15: =(J15/L15)*100 -> 0 | L15: =L14 -> 0.034
A16: Sat | B16: C17:0 | D16: =VLOOKUP(B16,'Reporte GC'!C1:H54,5,FALSE) -> 14.639886 | E16: 1.0441 | F16: =O$21 -> 0.0020467305 | G16: =(D16*F16*1*E16)/$D$44 -> 3.7752233e-05 | H16: 0.9507 | I16: =D16*100/$D$52 -> 0.11208537 | J16: =H16*G16 -> 3.5891048e-05 | K16: =(J16/L16)*100 -> 0.10556191 | L16: =L15 -> 0.034
A17: P.insat | B17: C16:3n4 | D17: =VLOOKUP(B17,'Reporte GC'!C1:H54,5,FALSE) -> 0 | E17: 1.031 | F17: =O$21 -> 0.0020467305 | G17: =(D17*F17*1*E17)/$D$44 -> 0 | H17: 0.9469 | I17: =D17*100/$D$52 -> 0 | J17: =H17*G17 -> 0 | K17: =(J17/L17)*100 -> 0 | L17: =L16 -> 0.034
A18: M.insat | B18: C17:1 | D18: =VLOOKUP(B18,'Reporte GC'!C1:H54,5,FALSE) -> 11.376917 | E18: 1.0367 | F18: =O$21 -> 0.0020467305 | G18: =(D18*F18*1*E18)/$D$44 -> 2.9130004e-05 | H18: 0.9503 | I18: =D18*100/$D$52 -> 0.087103547 | J18: =H18*G18 -> 2.7682243e-05 | K18: =(J18/L18)*100 -> 0.081418361 | L18: =L17 -> 0.034
A19: P.insat | B19: C16:4n1 | D19: =VLOOKUP(B19,'Reporte GC'!C1:H54,5,FALSE) -> 0 | E19: 1.0232 | F19: =O$21 -> 0.0020467305 | G19: =(D19*F19*1*E19)/$D$44 -> 0 | H19: 0.9465 | I19: =D19*100/$D$52 -> 0 | J19: =H19*G19 -> 0 | K19: =(J19/L19)*100 -> 0 | L19: =L18 -> 0.034 | N19: JOB* | O19: OSO1R1
A20: Sat | B20: C18:0 | D20: =VLOOKUP(B20,'Reporte GC'!C1:H54,5,FALSE) -> 228.77031 | E20: 1.0347 | F20: =O$21 -> 0.0020467305 | G20: =(D20*F20*1*E20)/$D$44 -> 0.00058462444 | H20: 0.953 | I20: =D20*100/$D$52 -> 1.7515031 | J20: =H20*G20 -> 0.00055714709 | K20: =(J20/L20)*100 -> 1.6386679 | L20: =L19 -> 0.034 | N20: grasa a metilar [g] | O20: Masa C23:0 [g] | P20: grasa Qco [g/100]
A21: M.insat | B21: C18:1n9 | C21: 25.937 | D21: =VLOOKUP(B21,'Reporte GC'!C1:H54,5,FALSE) -> 382.97647 | E21: 1.0277 | F21: =O$21 -> 0.0020467305 | G21: =(D21*F21*1*E21)/$D$44 -> 0.00097207844 | H21: 0.9527 | I21: =D21*100/$D$52 -> 2.9321309 | J21: =H21*G21 -> 0.00092609913 | K21: =(J21/L21)*100 -> 2.723821 | L21: =L20 -> 0.034 | N21: =VLOOKUP(O19,Resultados!A1:D34,2,FALSE) -> 0.034 | O21: =VLOOKUP(O19,'Concentración C23'!A4:C37,3,FALSE) -> 0.0020467305 | P21: =VLOOKUP(O19,Resultados!A1:D34,3,FALSE) -> 0.0020467305
A22: Trans | B22: C18:1n9t | D22: =VLOOKUP(B22,'Reporte GC'!C1:H54,5,FALSE) -> 7094.5708 | E22: 1.0277 | F22: =O$21 -> 0.0020467305 | G22: =(D22*F22*1*E22)/$D$44 -> 0.01800758 | H22: 0.9527 | I22: =D22*100/$D$52 -> 54.317201 | J22: =H22*G22 -> 0.017155821 | K22: =(J22/L22)*100 -> 50.458297 | L22: =L21 -> 0.034
A23: M.insat | B23: C18:1n7 | D23: =VLOOKUP(B23,'Reporte GC'!C1:H54,5,FALSE) -> 0 | E23: 1.0277 | F23: =O$21 -> 0.0020467305 | G23: =(D23*F23*1*E23)/$D$44 -> 0 | H23: 0.9527 | I23: =D23*100/$D$52 -> 0 | J23: =H23*G23 -> 0 | K23: =(J23/L23)*100 -> 0 | L23: =L22 -> 0.034
A24: P.insat | B24: C18:2n6 | C24: 27.334 | D24: =VLOOKUP(B24,'Reporte GC'!C1:H54,5,FALSE) -> 2237.9451 | E24: 1.0207 | F24: =O$21 -> 0.0020467305 | G24: =(D24*F24*1*E24)/$D$44 -> 0.0056417053 | H24: 0.9524 | I24: =D24*100/$D$52 -> 17.134076 | J24: =H24*G24 -> 0.0053731601 | K24: =(J24/L24)*100 -> 15.803412 | L24: =L23 -> 0.034
A25: Trans | B25: C18:2n6t | D25: =VLOOKUP(B25,'Reporte GC'!C1:H54,5,FALSE) -> 0 | E25: 1.0207 | F25: =O$21 -> 0.0020467305 | G25: =(D25*F25*1*E25)/$D$44 -> 0 | H25: 0.9524 | I25: =D25*100/$D$52 -> 0 | J25: =H25*G25 -> 0 | K25: =(J25/L25)*100 -> 0 | L25: =L24 -> 0.034
A26: P.insat | B26: C18:2n4 | D26: =VLOOKUP(B26,'Reporte GC'!C1:H54,5,FALSE) -> 0 | E26: 1.0207 | F26: =O$21 -> 0.0020467305 | G26: =(D26*F26*1*E26)/$D$44 -> 0 | H26: 0.9524 | I26: =D26*100/$D$52 -> 0 | J26: =H26*G26 -> 0 | K26: =(J26/L26)*100 -> 0 | L26: =L25 -> 0.034
A27: P.insat | B27: C18:3n6 | C27: 28.156 | D27: =VLOOKUP(B27,'Reporte GC'!C1:H54,5,FALSE) -> 0 | E27: 1.0137 | F27: =O$21 -> 0.0020467305 | G27: =(D27*F27*1*E27)/$D$44 -> 0 | H27: 0.952 | I27: =D27*100/$D$52 -> 0 | J27: =H27*G27 -> 0 | K27: =(J27/L27)*100 -> 0 | L27: =L26 -> 0.034
A28: P.insat | B28: C18:3n4 | D28: =VLOOKUP(B28,'Reporte GC'!C1:H54,5,FALSE) -> 7.4130731 | E28: 1.0137 | F28: =O$21 -> 0.0020467305 | G28: =(D28*F28*1*E28)/$D$44 -> 1.8559684e-05 | H28: 0.952 | I28: =D28*100/$D$52 -> 0.056755707 | J28: =H28*G28 -> 1.766882e-05 | K28: =(J28/L28)*100 -> 0.051967116 | L28: =L27 -> 0.034
A29: P.insat | B29: C18:3n3 | C29: 29.249 | D29: =VLOOKUP(B29,'Reporte GC'!C1:H54,5,FALSE) -> 1160.8749 | E29: 1.0137 | F29: =O$21 -> 0.0020467305 | G29: =(D29*F29*1*E29)/$D$44 -> 0.0029064156 | H29: 0.952 | I29: =D29*100/$D$52 -> 8.887849 | J29: =H29*G29 -> 0.0027669077 | K29: =(J29/L29)*100 -> 8.1379637 | L29: =L28 -> 0.034
A30: P.insat | B30: C18:4n3 | D30: =VLOOKUP(B30,'Reporte GC'!C1:H54,5,FALSE) -> 0 | E30: 1.0067 | F30: =O$21 -> 0.0020467305 | G30: =(D30*F30*1*E30)/$D$44 -> 0 | H30: 0.9517 | I30: =D30*100/$D$52 -> 0 | J30: =H30*G30 -> 0 | K30: =(J30/L30)*100 -> 0 | L30: =L29 -> 0.034
A31: Sat | B31: C20:0 | C31: 31.644 | D31: =VLOOKUP(B31,'Reporte GC'!C1:H54,5,FALSE) -> 66.078186 | E31: 1.0187 | F31: =O$21 -> 0.0020467305 | G31: =(D31*F31*1*E31)/$D$44 -> 0.00016625215 | H31: 0.957 | I31: =D31*100/$D$52 -> 0.50590546 | J31: =H31*G31 -> 0.00015910331 | K31: =(J31/L31)*100 -> 0.46795091 | L31: =L30 -> 0.034
A32: M.insat | B32: C20:1n11 | D32: =VLOOKUP(B32,'Reporte GC'!C1:H54,5,FALSE) -> 149.83345 | E32: 1.0124 | F32: =O$21 -> 0.0020467305 | G32: =(D32*F32*1*E32)/$D$44 -> 0.00037464831 | H32: 0.9568 | I32: =D32*100/$D$52 -> 1.1471495 | J32: =H32*G32 -> 0.0003584635 | K32: =(J32/L32)*100 -> 1.0543044 | L32: =L31 -> 0.034
A33: M.insat | B33: C20:1n9 | C33: 32.21 | D33: =VLOOKUP(B33,'Reporte GC'!C1:H54,5,FALSE) -> 0 | E33: 1.0124 | F33: =O$21 -> 0.0020467305 | G33: =(D33*F33*1*E33)/$D$44 -> 0 | H33: 0.9568 | I33: =D33*100/$D$52 -> 0 | J33: =H33*G33 -> 0 | K33: =(J33/L33)*100 -> 0 | L33: =L32 -> 0.034
A34: P.insat | B34: C20:2n6 | C34: 33.56 | D34: =VLOOKUP(B34,'Reporte GC'!C1:H54,5,FALSE) -> 0 | E34: 1.0061 | F34: =O$21 -> 0.0020467305 | G34: =(D34*F34*1*E34)/$D$44 -> 0 | H34: 0.9565 | I34: =D34*100/$D$52 -> 0 | J34: =H34*G34 -> 0 | K34: =(J34/L34)*100 -> 0 | L34: =L33 -> 0.034
A35: P.insat | B35: C20:3n6 | C35: 34.286 | D35: =VLOOKUP(B35,'Reporte GC'!C1:H54,5,FALSE) -> 0 | E35: 1.0065 | F35: =O$21 -> 0.0020467305 | G35: =(D35*F35*1*E35)/$D$44 -> 0 | H35: 0.9562 | I35: =D35*100/$D$52 -> 0 | J35: =H35*G35 -> 0 | K35: =(J35/L35)*100 -> 0 | L35: =L34 -> 0.034
A36: Sat | B36: C21:0 | C36: 34.732 | D36: =VLOOKUP(B36,'Reporte GC'!C1:H54,5,FALSE) -> 0 | E36: 1.0119 | F36: =O$21 -> 0.0020467305 | G36: =(D36*F36*1*E36)/$D$44 -> 0 | H36: 0.9588 | I36: =D36*100/$D$52 -> 0 | J36: =H36*G36 -> 0 | K36: =(J36/L36)*100 -> 0 | L36: =L35 -> 0.034
A37: P.insat | B37: C20:4n6 | C37: 35.093 | D37: =VLOOKUP(B37,'Reporte GC'!C1:H54,5,FALSE) -> 0 | E37: 0.9976 | F37: =O$21 -> 0.0020467305 | G37: =(D37*F37*1*E37)/$D$44 -> 0 | H37: 0.9633 | I37: =D37*100/$D$52 -> 0 | J37: =H37*G37 -> 0 | K37: =(J37/L37)*100 -> 0 | L37: =L36 -> 0.034
A38: P.insat | B38: C20:3n3 | C38: 35.598 | D38: =VLOOKUP(B38,'Reporte GC'!C1:H54,5,FALSE) -> 0 | E38: 1.0065 | F38: =O$21 -> 0.0020467305 | G38: =(D38*F38*1*E38)/$D$44 -> 0 | H38: =0.9562 -> 0.9562 | I38: =D38*100/$D$52 -> 0 | J38: =H38*G38 -> 0 | K38: =(J38/L38)*100 -> 0 | L38: =L37 -> 0.034
A39: P.insat | B39: C20:4n3 | D39: =VLOOKUP(B39,'Reporte GC'!C1:H54,5,FALSE) -> 0 | E39: 0.9976 | F39: =O$21 -> 0.0020467305 | G39: =(D39*F39*1*E39)/$D$44 -> 0 | H39: 0.956 | I39: =D39*100/$D$52 -> 0 | J39: =H39*G39 -> 0 | K39: =(J39/L39)*100 -> 0 | L39: =L38 -> 0.034
A40: P.insat | B40: C20:5n3 | C40: 36.927 | D40: =VLOOKUP(B40,'Reporte GC'!C1:H54,5,FALSE) -> 510.78226 | E40: 0.998 | F40: =O$21 -> 0.0020467305 | G40: =(D40*F40*1*E40)/$D$44 -> 0.0012590101 | H40: 0.9557 | I40: =D40*100/$D$52 -> 3.910633 | J40: =H40*G40 -> 0.0012032359 | K40: =(J40/L40)*100 -> 3.5389292 | L40: =L39 -> 0.034 | W40: =L39 -> 0.034
...

Sheet Resultados
A1: Job | B1: Grasa a metilar [g] | C1: Masa SI [g] | D1: Ácidos grasos [µg/g] (sólo biotas)
A2: OSO1R1 | B2: 0.034 | C2: ='Concentración C23'!C5 -> 0.0020467305
C3: ='Concentración C23'!C6 -> 0
C4: ='Concentración C23'!C7 -> 0
C5: ='Concentración C23'!C8 -> 0
C6: ='Concentración C23'!C9 -> 0
C7: ='Concentración C23'!C10 -> 0 | K7: Datos de entrada
C8: ='Concentración C23'!C11 -> 0
C9: ='Concentración C23'!C12 -> 0
C10: ='Concentración C23'!C13 -> 0
C11: ='Concentración C23'!C14 -> 0
C12: ='Concentración C23'!C15 -> 0
C13: ='Concentración C23'!C16 -> 0
C14: ='Concentración C23'!C17 -> 0
C15: ='Concentración C23'!C18 -> 0
C16: ='Concentración C23'!C19 -> 0
C17: ='Concentración C23'!C20 -> 0
C18: ='Concentración C23'!C21 -> 0
C19: ='Concentración C23'!C22 -> 0
... C34: ='Concentración C23'!C37 -> 0

Sheet Concentración C23
B2: [C23:0] en solucion | C2: =H15 -> 0.01364487 | D2: g de C23/g de solucion | G2: Densidad ISOCTANO | H2: a 20°C
G3: 0.69663 | H3: g/ml
A4: Job | B4: Masa solución C23 [g] | C4: Masa C23 [g]
A5: OSO1R1 | B5: 0.15 | C5: =$C$2*B5 -> 0.0020467305 | G5: Concentracion mg/ml
C6: =$C$2*B6 -> 0 | G6: Peso C23 | H6: 0.0960144 | I6: g
C7: =$C$2*B7 -> 0 | G7: Aforo | H7: 10 | I7: ml
C8: =$C$2*B8 -> 0 | G8: mg/ml | H8: =H6*1000/H7 -> 9.60144 | I8: mg/ml
C9: =$C$2*B9 -> 0 | G9: Correccion Pureza | H9: =H8*0.99 -> 9.5054256 | I9: mg/ml
C10: =$C$2*B10 -> 0
C11: =$C$2*B11 -> 0 | G11: Concentracion: g de c23/1 g de isoctano
C12: =$C$2*B12 -> 0 | G12: Peso C23 | H12: =H6 -> 0.0960144 | I12: g
C13: =$C$2*B13 -> 0 | G13: Aforo | H13: =G3*H7 -> 6.9663 | I13: g
C14: =$C$2*B14 -> 0 | G14: Concentración en masa | H14: =H12/H13 -> 0.013782697 | I14: g/g
C15: =$C$2*B15 -> 0 | G15: Concentración corregida por pureza | H15: =H14*0.99 -> 0.01364487 | I15: g/g
C16: =$C$2*B16 -> 0
C17: =$C$2*B17 -> 0
C18: =$C$2*B18 -> 0
C19: =$C$2*B19 -> 0
C20: =$C$2*B20 -> 0
C21: =$C$2*B21 -> 0 | G21: Datos de entrada
C22: =$C$2*B22 -> 0
C23: =$C$2*B23 -> 0
C24: =$C$2*B24 -> 0
C25: =$C$2*B25 -> 0
C26: =$C$2*B26 -> 0
C27: =$C$2*B27 -> 0
C28: =$C$2*B28 -> 0
C29: =$C$2*B29 -> 0
C30: =$C$2*B30 -> 0
C31: =$C$2*B31 -> 0
C32: =$C$2*B32 -> 0
C33: =$C$2*B33 -> 0
... C37: =$C$2*B37 -> 0

Sheet AFOCR_AC_GRASOS_A (CCLAS)
BZ3: EPA | CR3: DHA
A4: XLS | B4: C4:0 | D4: C6:0 | F4: C8:0 | H4: C10:0 | J4: C11:0 | L4: C12:0 | N4: C13:0 | P4: C14:0 | R4: C14:1 | T4: C15:0 | V4: C15:1 | X4: C16:0 | Z4: C16:1 | AB4: C16:2n4 | AD4: C17:0 | AF4: C16:3n4 | AH4: C17:1 | AJ4: C16:4n1 | AL4: C18:0 | AN4: C18:1n9 | AP4: C18:1n9t | AR4: C18:1n7 | AT4: C18:2n6 | AV4: C18:2n6t | AX4: C18:2n4 | AZ4: C18:3n6 | BB4: C18:3n4 | BD4: C18:3n3 | BF4: C18:4n3 | BH4: C20:0 | BJ4: C20:1n11 | BL4: C20:1n9 | BN4: C20:2n6 | BP4: C20:3n6 | BR4: C21:0 | BT4: C20:4n6 | BV4: C20:3n3 | BX4: C20:4n3 | BZ4: C20:5n3 | CB4: C22:0 | CD4: C22:1n9 | CF4: C22:2n6 | CH4: C23:0 | CJ4: C21:5n3 | CL4: C22:5n6 | CN4: C22:5n3 | CP4: C24:0 | CR4: C22:6n3 | CT4: C24:1n9 | CV4: Unknow
B5: % Area | C5: Area FAMEx | D5: % Area | E5: Area FAMEx | F5: % Area | G5: Area FAMEx | H5: % Area | I5: Area FAMEx | J5: % Area | K5: Area FAMEx | L5: % Area | M5: Area FAMEx | N5: % Area | O5: Area FAMEx | P5: % Area | Q5: Area FAMEx | R5: % Area | S5: Area FAMEx | T5: % Area | U5: Area FAMEx | V5: % Area | W5: Area FAMEx | X5: % Area | Y5: Area FAMEx | Z5: % Area | AA5: Area FAMEx | AB5: % Area | AC5: Area FAMEx | AD5: % Area | AE5: Area FAMEx | AF5: % Area | AG5: Area FAMEx | AH5: % Area | AI5: Area FAMEx | AJ5: % Area | AK5: Area FAMEx | AL5: % Area | AM5: Area FAMEx | AN5: % Area | AO5: Area FAMEx | AP5: % Area | AQ5: Area FAMEx | AR5: % Area | AS5: Area FAMEx | AT5: % Area | AU5: Area FAMEx | AV5: % Area | AW5: Area FAMEx | AX5: % Area | AY5: Area FAMEx | AZ5: % Area | BA5: Area FAMEx | BB5: % Area | BC5: Area FAMEx | BD5: % Area | BE5: Area FAMEx | BF5: % Area | BG5: Area FAMEx | BH5: % Area | BI5: Area FAMEx | BJ5: % Area | BK5: Area FAMEx | BL5: % Area | BM5: Area FAMEx | BN5: % Area | BO5: Area FAMEx | BP5: % Area | BQ5: Area FAMEx | BR5: % Area | BS5: Area FAMEx | BT5: % Area | BU5: Area FAMEx | BV5: % Area | BW5: Area FAMEx | BX5: % Area | BY5: Area FAMEx | BZ5: % Area | CA5: Area FAMEx | CB5: % Area | CC5: Area FAMEx | CD5: % Area | CE5: Area FAMEx | CF5: % Area | CG5: Area FAMEx | CH5: % Area | CI5: Area FAMEx | CJ5: % Area | CK5: Area FAMEx | CL5: % Area | CM5: Area FAMEx | CN5: % Area | CO5: Area FAMEx | CP5: % Area | CQ5: Area FAMEx | CR5: % Area | CS5: Area FAMEx | CT5: % Area | CU5: Area FAMEx | CV5: % AreaNOIDENT. | CW5: Area FAMEx
B6: =VLOOKUP(B4,Tipo!$B$2:$I$50,8,FALSE) -> 0 | C6: =VLOOKUP(B4,Tipo!$B$2:$I$50,3,FALSE) -> 0 | D6: =VLOOKUP(D4,Tipo!$B$2:$I$50,8,FALSE) -> 0 | E6: =VLOOKUP(D4,Tipo!$B$2:$I$50,3,FALSE) -> 0 | F6: =VLOOKUP(F4,Tipo!$B$2:$I$50,8,FALSE) -> 0 | G6: =VLOOKUP(F4,Tipo!$B$2:$I$50,3,FALSE) -> 0 | H6: =VLOOKUP(H4,Tipo!$B$2:$I$50,8,FALSE) -> 0 | I6: =VLOOKUP(H4,Tipo!$B$2:$I$50,3,FALSE) -> 0 | J6: =VLOOKUP(J4,Tipo!$B$2:$I$50,8,FALSE) -> 0 | K6: =VLOOKUP(J4,Tipo!$B$2:$I$50,3,FALSE) -> 0 | L6: =VLOOKUP(L4,Tipo!$B$2:$I$50,8,FALSE) -> 0 | M6: =VLOOKUP(L4,Tipo!$B$2:$I$50,3,FALSE) -> 0 | N6: =VLOOKUP(N4,Tipo!$B$2:$I$50,8,FALSE) -> 0 | O6: =VLOOKUP(N4,Tipo!$B$2:$I$50,3,FALSE) -> 0 | P6: =VLOOKUP(P4,Tipo!$B$2:$I$50,8,FALSE) -> 0.15552976 | Q6: =VLOOKUP(P4,Tipo!$B$2:$I$50,3,FALSE) -> 20.314318 | R6: =VLOOKUP(R4,Tipo!$B$2:$I$50,8,FALSE) -> 0 | S6: =VLOOKUP(R4,Tipo!$B$2:$I$50,3,FALSE) -> 0 | T6: =VLOOKUP(T4,Tipo!$B$2:$I$50,8,FALSE) -> 0 | U6: =VLOOKUP(T4,Tipo!$B$2:$I$50,3,FALSE) -> 0 | V6: =VLOOKUP(V4,Tipo!$B$2:$I$50,8,FALSE) -> 0 | W6: =VLOOKUP(V4,Tipo!$B$2:$I$50,3,FALSE) -> 0 | X6: =VLOOKUP(X4,Tipo!$B$2:$I$50,8,FALSE) -> 4.0492652 | Y6: =VLOOKUP(X4,Tipo!$B$2:$I$50,3,FALSE) -> 528.88953 | Z6: =VLOOKUP(Z4,Tipo!$B$2:$I$50,8,FALSE) -> 0.22789458 | AA6: =VLOOKUP(Z4,Tipo!$B$2:$I$50,3,FALSE) -> 29.766155 | AB6: =VLOOKUP(AB4,Tipo!$B$2:$I$50,8,FALSE) -> 0 | AC6: =VLOOKUP(AB4,Tipo!$B$2:$I$50,3,FALSE) -> 0 | AD6: =VLOOKUP(AD4,Tipo!$B$2:$I$50,8,FALSE) -> 0.11208537 | AE6: =VLOOKUP(AD4,Tipo!$B$2:$I$50,3,FALSE) -> 14.639886 | AF6: =VLOOKUP(AF4,Tipo!$B$2:$I$50,8,FALSE) -> 0 | AG6: =VLOOKUP(AF4,Tipo!$B$2:$I$50,3,FALSE) -> 0 | AH6: =VLOOKUP(AH4,Tipo!$B$2:$I$50,8,FALSE) -> 0.087103547 | AI6: =VLOOKUP(AH4,Tipo!$B$2:$I$50,3,FALSE) -> 11.376917 | AJ6: =VLOOKUP(AJ4,Tipo!$B$2:$I$50,8,FALSE) -> 0 | AK6: =VLOOKUP(AJ4,Tipo!$B$2:$I$50,3,FALSE) -> 0 | AL6: =VLOOKUP(AL4,Tipo!$B$2:$I$50,8,FALSE) -> 1.7515031 | AM6: =VLOOKUP(AL4,Tipo!$B$2:$I$50,3,FALSE) -> 228.77031 | AN6: =VLOOKUP(AN4,Tipo!$B$2:$I$50,8,FALSE) -> 2.9321309 | AO6: =VLOOKUP(AN4,Tipo!$B$2:$I$50,3,FALSE) -> 382.97647 | AP6: =VLOOKUP(AP4,Tipo!$B$2:$I$50,8,FALSE) -> 54.317201 | AQ6: =VLOOKUP(AP4,Tipo!$B$2:$I$50,3,FALSE) -> 7094.5708 | AR6: =VLOOKUP(AR4,Tipo!$B$2:$I$50,8,FALSE) -> 0 | AS6: =VLOOKUP(AR4,Tipo!$B$2:$I$50,3,FALSE) -> 0 | AT6: =VLOOKUP(AT4,Tipo!$B$2:$I$50,8,FALSE) -> 17.134076 | AU6: =VLOOKUP(AT4,Tipo!$B$2:$I$50,3,FALSE) -> 2237.9451 | AV6: =VLOOKUP(AV4,Tipo!$B$2:$I$50,8,FALSE) -> 0 | AW6: =VLOOKUP(AV4,Tipo!$B$2:$I$50,3,FALSE) -> 0 | AX6: =VLOOKUP(AX4,Tipo!$B$2:$I$50,8,FALSE) -> 0 | AY6: =VLOOKUP(AX4,Tipo!$B$2:$I$50,3,FALSE) -> 0 | AZ6: =VLOOKUP(AZ4,Tipo!$B$2:$I$50,8,FALSE) -> 0 | BA6: =VLOOKUP(AZ4,Tipo!$B$2:$I$50,3,FALSE) -> 0 | BB6: =VLOOKUP(BB4,Tipo!$B$2:$I$50,8,FALSE) -> 0.056755707 | BC6: =VLOOKUP(BB4,Tipo!$B$2:$I$50,3,FALSE) -> 7.4130731 | BD6: =VLOOKUP(BD4,Tipo!$B$2:$I$50,8,FALSE) -> 8.887849 | BE6: =VLOOKUP(BD4,Tipo!$B$2:$I$50,3,FALSE) -> 1160.8749 | BF6: =VLOOKUP(BF4,Tipo!$B$2:$I$50,8,FALSE) -> 0 | BG6: =VLOOKUP(BF4,Tipo!$B$2:$I$50,3,FALSE) -> 0 | BH6: =VLOOKUP(BH4,Tipo!$B$2:$I$50,8,FALSE) -> 0.50590546 | BI6: =VLOOKUP(BH4,Tipo!$B$2:$I$50,3,FALSE) -> 66.078186 | BJ6: =VLOOKUP(BJ4,Tipo!$B$2:$I$50,8,FALSE) -> 1.1471495 | BK6: =VLOOKUP(BJ4,Tipo!$B$2:$I$50,3,FALSE) -> 149.83345 | BL6: =VLOOKUP(BL4,Tipo!$B$2:$I$50,8,FALSE) -> 0 | BM6: =VLOOKUP(BL4,Tipo!$B$2:$I$50,3,FALSE) -> 0 | BN6: =VLOOKUP(BN4,Tipo!$B$2:$I$50,8,FALSE) -> 0 | BO6: =VLOOKUP(BN4,Tipo!$B$2:$I$50,3,FALSE) -> 0 | BP6: =VLOOKUP(BP4,Tipo!$B$2:$I$50,8,FALSE) -> 0 | BQ6: =VLOOKUP(BP4,Tipo!$B$2:$I$50,3,FALSE) -> 0 | BR6: =VLOOKUP(BR4,Tipo!$B$2:$I$50,8,FALSE) -> 0 | BS6: =VLOOKUP(BR4,Tipo!$B$2:$I$50,3,FALSE) -> 0 | BT6: =VLOOKUP(BT4,Tipo!$B$2:$I$50,8,FALSE) -> 0 | BU6: =VLOOKUP(BT4,Tipo!$B$2:$I$50,3,FALSE) -> 0 | BV6: =VLOOKUP(BV4,Tipo!$B$2:$I$50,8,FALSE) -> 0 | BW6: =VLOOKUP(BV4,Tipo!$B$2:$I$50,3,FALSE) -> 0 | BX6: =VLOOKUP(BX4,Tipo!$B$2:$I$50,8,FALSE) -> 0 | BY6: =VLOOKUP(BX4,Tipo!$B$2:$I$50,3,FALSE) -> 0 | BZ6: =VLOOKUP(BZ4,Tipo!$B$2:$I$50,8,FALSE) -> 3.910633 | CA6: =VLOOKUP(BZ4,Tipo!$B$2:$I$50,3,FALSE) -> 510.78226 | CB6: =VLOOKUP(CB4,Tipo!$B$2:$I$50,8,FALSE) -> 0.28490348 | CC6: =VLOOKUP(CB4,Tipo!$B$2:$I$50,3,FALSE) -> 37.212299 | CD6: =VLOOKUP(CD4,Tipo!$B$2:$I$50,8,FALSE) -> 0 | CE6: =VLOOKUP(CD4,Tipo!$B$2:$I$50,3,FALSE) -> 0 | CF6: =VLOOKUP(CF4,Tipo!$B$2:$I$50,8,FALSE) -> 0 | CG6: =VLOOKUP(CF4,Tipo!$B$2:$I$50,3,FALSE) -> 0 | CH6: =VLOOKUP(CH4,Tipo!$B$2:$I$50,8,FALSE) -> 0 | CI6: =VLOOKUP(CH4,Tipo!$B$2:$I$50,3,FALSE) -> 828.70087 | CJ6: =VLOOKUP(CJ4,Tipo!$B$2:$I$50,8,FALSE) -> 0 | CK6: =VLOOKUP(CJ4,Tipo!$B$2:$I$50,3,FALSE) -> 0 | CL6: =VLOOKUP(CL4,Tipo!$B$2:$I$50,8,FALSE) -> 0 | CM6: =VLOOKUP(CL4,Tipo!$B$2:$I$50,3,FALSE) -> 0 | CN6: =VLOOKUP(CN4,Tipo!$B$2:$I$50,8,FALSE) -> 0.13644881 | CO6: =VLOOKUP(CN4,Tipo!$B$2:$I$50,3,FALSE) -> 17.822084 | CP6: =VLOOKUP(CP4,Tipo!$B$2:$I$50,8,FALSE) -> 0 | CQ6: =VLOOKUP(CP4,Tipo!$B$2:$I$50,3,FALSE) -> 0 | CR6: =VLOOKUP(CR4,Tipo!$B$2:$I$50,8,FALSE) -> 4.1253969 | CS6: =VLOOKUP(CR4,Tipo!$B$2:$I$50,3,FALSE) -> 538.83337 | CT6: =VLOOKUP(CT4,Tipo!$B$2:$I$50,8,FALSE) -> 0.16176001 | CU6: =VLOOKUP(CT4,Tipo!$B$2:$I$50,3,FALSE) -> 21.128075 | CV6: =VLOOKUP(CV4,Tipo!$B$2:$I$51,8,FALSE) -> 0.016409018 | CW6: =VLOOKUP(CV4,Tipo!$B$2:$I$51,3,FALSE) -> 2.1432426

Sheet AFOCR_AC_GRASOS_100G (CCLAS)
A3: XLS g/100g
B4: C4:0 | C4: C6:0 | D4: C8:0 | E4: C10:0 | F4: C11:0 | G4: C12:0 | H4: C13.0 | I4: C14:0 | J4: C14:1 | K4: C15:0 | L4: C15:1 | M4: C16:0 | N4: C16:1 | O4: C16:2n4 | P4: C17:0 | Q4: C16:3n4 | R4: C17:1 | S4: C16:4n1 | T4: C18:0 | U4: C18:1n9 | V4: C18:1t | W4: C18:1n7 | X4: C18:2n6 | Y4: C18:2t+t | Z4: C18:2n4 | AA4: C18:3n6 | AB4: C18:3n4 | AC4: C18:3n3 | AD4: C18:4 n3 | AE4: C20:0 | AF4: C20:1n11+ | AG4: C20:1n9 | AH4: C20:2n6 | AI4: C20:3n6 | AJ4: C21:0 | AK4: C20:4n6 | AL4: C20:3n3 | AM4: C20:4n3 | AN4: C20:5n3 | AO4: C22:0 | AP4: C22:1n9 | AQ4: C22:2n6 | AR4: C23:0 | AS4: C21:5n3 | AT4: C22:5n6 | AU4: C22:5n3 | AV4: C24:0 | AW4: C22:6n3 | AX4: C24:1 | AY4: Unknow
B5: =Tipo!K2 -> 0 | C5: =Tipo!K3 -> 0 | D5: =Tipo!K4 -> 0 | E5: =Tipo!K5 -> 0 | F5: =Tipo!K6 -> 0 | G5: =Tipo!K7 -> 0 | H5: =Tipo!K8 -> 0 | I5: =Tipo!K9 -> 0.15017144 | J5: =Tipo!K10 -> 0 | K5: =Tipo!K11 -> 0 | L5: =Tipo!K12 -> 0 | M5: =Tipo!K13 -> 3.8414114 | N5: =Tipo!K14 -> 0.21450691 | O5: =Tipo!K15 -> 0 | P5: =Tipo!K16 -> 0.10556191 | Q5: =Tipo!K17 -> 0 | R5: =Tipo!K18 -> 0.081418361 | S5: =Tipo!K19 -> 0 | T5: =Tipo!K20 -> 1.6386679 | U5: =Tipo!K21 -> 2.723821 | V5: =Tipo!K22 -> 50.458297 | W5: =Tipo!K23 -> 0 | X5: =Tipo!K24 -> 15.803412 | Y5: =Tipo!K25 -> 0 | Z5: =Tipo!K26 -> 0 | AA5: =Tipo!K27 -> 0 | AB5: =Tipo!K28 -> 0.051967116 | AC5: =Tipo!K29 -> 8.1379637 | AD5: =Tipo!K30 -> 0 | AE5: =Tipo!K31 -> 0.46795091 | AF5: =Tipo!K32 -> 1.0543044 | AG5: =Tipo!K33 -> 0 | AH5: =Tipo!K34 -> 0 | AI5: =Tipo!K35 -> 0 | AJ5: =Tipo!K36 -> 0 | AK5: =Tipo!K37 -> 0 | AL5: =Tipo!K38 -> 0 | AM5: =Tipo!K39 -> 0 | AN5: =Tipo!K40 -> 3.5389292 | AO5: =Tipo!K41 -> 0.26109049 | AP5: =Tipo!K42 -> 0 | AQ5: =Tipo!K43 -> 0 | AR5: =Tipo!K44 -> 0 | AS5: =Tipo!K45 -> 0 | AT5: =Tipo!K46 -> 0 | AU5: =Tipo!K47 -> 0.12621728 | AV5: =Tipo!K48 -> 0 | AW5: =Tipo!K49 -> 3.8456433 | AX5: =Tipo!K50 -> 0.14627663 | AY5: =Tipo!K51 -> 0.014790365

Sheet Reporte GC
A1: HeaderName | B1: HeaderValue | C1: segName | D1: Timestart | E1: Timeend | F1: Height | G1: Area | H1: PPM | I1: ISTDName | J1: RF | K1: Signal
A2: NumberOfRows | B2: 48 | C2: C4:0 | D2: 0 | E2: 0 | F2: 0 | G2: 0 | H2: 0 | J2: 0 | K2: 1
A3: NumberOfCol | B3: 9 | C3: C6:0 | D3: 0 | E3: 0 | F3: 0 | G3: 0 | H3: 0 | J3: 0 | K3: 1
A4: NumberOfHead | B4: 10 | C4: C8:0 | D4: 0 | E4: 0 | F4: 0 | G4: 0 | H4: 0 | J4: 0 | K4: 1
A5: Modified | B5: 1 | C5: C10:0 | D5: 0 | E5: 0 | F5: 0 | G5: 0 | H5: 0 | J5: 0 | K5: 1 | T5: Cargar hoja "PeakSumCalcT1$" en celda "A1" yendo a Datos->Conexiones existentes->Examinar->Report01.xls (Asociado a resultados que entrega el GC)
A6: total | B6: 99.98457 | C6: C11:0 | D6: 0 | E6: 0 | F6: 0 | G6: 0 | H6: 0 | J6: 0 | K6: 1
A7: total1 | B7: 0 | C7: C12:0 | D7: 0 | E7: 0 | F7: 0 | G7: 0 | H7: 0 | J7: 0 | K7: 1
A8: multiplier | B8: 1 | C8: C13:0 | D8: 0 | E8: 0 | F8: 0 | G8: 0 | H8: 0 | J8: 0 | K8: 1
A9: dilution | B9: 1 | C9: C14:0 | D9: 0 | E9: 0 | F9: 0 | G9: 20.314318 | H9: 0.14625064 | J9: 0 | K9: 1
A10: sampleAmt | B10: 0 | C10: C14:1 | D10: 0 | E10: 0 | F10: 0 | G10: 0 | H10: 0 | J10: 0 | K10: 1
A11: TotPeakResponse | B11: 13890.071 | C11: C15:0 | D11: 0 | E11: 0 | F11: 0 | G11: 0 | H11: 0 | J11: 0 | K11: 1
C12: C15:1 | D12: 0 | E12: 0 | F12: 0 | G12: 0 | H12: 0 | J12: 0 | K12: 1
C13: C16:0 | D13: 0 | E13: 0 | F13: 0 | G13: 528.88953 | H13: 3.8076804 | J13: 0 | K13: 1
C14: C16:1 | D14: 0 | E14: 0 | F14: 0 | G14: 29.766155 | H14: 0.21429807 | J14: 0 | K14: 1
C15: C16:2n4 | D15: 0 | E15: 0 | F15: 0 | G15: 0 | H15: 0 | J15: 0 | K15: 1
C16: C17:0 | D16: 0 | E16: 0 | F16: 0 | G16: 14.639886 | H16: 0.10539821 | J16: 0 | K16: 1
C17: C16:3n4 | D17: 0 | E17: 0 | F17: 0 | G17: 0 | H17: 0 | J17: 0 | K17: 1
C18: C17:1 | D18: 0 | E18: 0 | F18: 0 | G18: 11.376917 | H18: 0.081906829 | J18: 0 | K18: 1
C19: C16:4n1 | D19: 0 | E19: 0 | F19: 0 | G19: 0 | H19: 0 | J19: 0 | K19: 1
C20: C18:0 | D20: 0 | E20: 0 | F20: 0 | G20: 228.77031 | H20: 1.647006 | J20: 0 | K20: 1
C21: C18:1n9t | D21: 0 | E21: 0 | F21: 0 | G21: 7094.5708 | H21: 51.076562 | J21: 0 | K21: 1
C22: C18:1n9 | D22: 0 | E22: 0 | F22: 0 | G22: 382.97647 | H22: 2.7571959 | J22: 0 | K22: 1
C23: C18:1n7 | D23: 0 | E23: 0 | F23: 0 | G23: 0 | H23: 0 | J23: 0 | K23: 1
... C49: C24:1n9 | D49: 0 | E49: 0 | F49: 0 | G49: 21.128075 | H49: 0.15210919 | J49: 0 | K49: 1
R56: % NI | S56: =(S60/S59)*100 -> 0.015430033 | AA56: *NI = No identificados
R57: % AG | S57: =SUM(H1:H51) -> 99.98457 | AA57: *AG = Ácidos grasos
R58: At sin NI | S58: =SUM(G1:G51) -> 13887.928 | AA58: *At = Área total
R59: At con NI | S59: =100*S58/S57 -> 13890.071
R60: Área NI | S60: =S59-S58 -> 2.1432426
